sia cosi:
train_masks = train_masks.reshape(train_masks.shape[0], -1)
val_masks = val_masks.reshape(val_masks.shape[0], -1)

model.fit(train_images, train_masks, epochs=epoch, batch_size=batch_size,
          callbacks=[early_stopping],class_weight = weights,
          validation_data=(val_images, val_masks))

sia cosi:
train_masks = train_masks.reshape(train_masks.shape[0], -1)

model.fit(train_images, train_masks, epochs=epoch, batch_size=batch_size,
          callbacks=[early_stopping],class_weight = weights,
          validation_data=(val_images, val_masks))

Epoch 1/300
---------------------------------------------------------------------------
ValueError                                Traceback (most recent call last)
<ipython-input-4-86267e660666> in <cell line: 36>()
     34 val_masks = val_masks.reshape(val_masks.shape[0], -1)
     35 
---> 36 model.fit(train_images, train_masks, epochs=epoch, batch_size=batch_size,
     37           callbacks=[early_stopping],class_weight = weights,
     38           validation_data=(val_images, val_masks))

1 frames
/usr/local/lib/python3.10/dist-packages/keras/engine/training.py in tf__train_function(iterator)
     13                 try:
     14                     do_return = True
---> 15                     retval_ = ag__.converted_call(ag__.ld(step_function), (ag__.ld(self), ag__.ld(iterator)), None, fscope)
     16                 except:
     17                     do_return = False

ValueError: in user code:

    File "/usr/local/lib/python3.10/dist-packages/keras/engine/training.py", line 1284, in train_function  *
        return step_function(self, iterator)
    File "/usr/local/lib/python3.10/dist-packages/keras/engine/training.py", line 1268, in step_function  **
        outputs = model.distribute_strategy.run(run_step, args=(data,))
    File "/usr/local/lib/python3.10/dist-packages/keras/engine/training.py", line 1249, in run_step  **
        outputs = model.train_step(data)
    File "/usr/local/lib/python3.10/dist-packages/keras/engine/training.py", line 1051, in train_step
        loss = self.compute_loss(x, y, y_pred, sample_weight)
    File "/usr/local/lib/python3.10/dist-packages/keras/engine/training.py", line 1109, in compute_loss
        return self.compiled_loss(
    File "/usr/local/lib/python3.10/dist-packages/keras/engine/compile_utils.py", line 265, in __call__
        loss_value = loss_obj(y_t, y_p, sample_weight=sw)
    File "/usr/local/lib/python3.10/dist-packages/keras/losses.py", line 142, in __call__
        losses = call_fn(y_true, y_pred)
    File "/usr/local/lib/python3.10/dist-packages/keras/losses.py", line 268, in call  **
        return ag_fn(y_true, y_pred, **self._fn_kwargs)
    File "/usr/local/lib/python3.10/dist-packages/keras/losses.py", line 2156, in binary_crossentropy
        backend.binary_crossentropy(y_true, y_pred, from_logits=from_logits),
    File "/usr/local/lib/python3.10/dist-packages/keras/backend.py", line 5707, in binary_crossentropy
        return tf.nn.sigmoid_cross_entropy_with_logits(

    ValueError: `logits` and `labels` must have the same shape, received ((None, 32, 32, 1) vs (None, 1024)).
